[2023-10-08 11:21:02,878] INFO _log() L96   192.168.0.15 - - [08/Oct/2023 11:21:02] "GET /processos HTTP/1.1" 200 - - call_trace=/home/phcosta/Documents/ticket/api/venv/lib/python3.11/site-packages/werkzeug/_internal.py L96  
[2023-10-08 11:21:15,791] INFO _log() L96    * Detected change in '/home/phcosta/Documents/ticket/api/model/analista/analista.py', reloading - call_trace=/home/phcosta/Documents/ticket/api/venv/lib/python3.11/site-packages/werkzeug/_internal.py L96  
[2023-10-08 11:28:23,211] INFO _log() L96   192.168.0.15 - - [08/Oct/2023 11:28:23] "GET /openapi/swagger HTTP/1.1" 200 - - call_trace=/home/phcosta/Documents/ticket/api/venv/lib/python3.11/site-packages/werkzeug/_internal.py L96  
[2023-10-08 11:28:23,236] INFO _log() L96   192.168.0.15 - - [08/Oct/2023 11:28:23] "[36mGET /openapi/static/css/swagger-ui.css HTTP/1.1[0m" 304 - - call_trace=/home/phcosta/Documents/ticket/api/venv/lib/python3.11/site-packages/werkzeug/_internal.py L96  
[2023-10-08 11:28:23,239] INFO _log() L96   192.168.0.15 - - [08/Oct/2023 11:28:23] "[36mGET /openapi/static/js/swagger-ui-standalone-preset.js HTTP/1.1[0m" 304 - - call_trace=/home/phcosta/Documents/ticket/api/venv/lib/python3.11/site-packages/werkzeug/_internal.py L96  
[2023-10-08 11:28:23,240] INFO _log() L96   192.168.0.15 - - [08/Oct/2023 11:28:23] "[36mGET /openapi/static/js/swagger-ui-bundle.js HTTP/1.1[0m" 304 - - call_trace=/home/phcosta/Documents/ticket/api/venv/lib/python3.11/site-packages/werkzeug/_internal.py L96  
[2023-10-08 11:28:23,335] INFO _log() L96   192.168.0.15 - - [08/Oct/2023 11:28:23] "GET /openapi/openapi.json HTTP/1.1" 200 - - call_trace=/home/phcosta/Documents/ticket/api/venv/lib/python3.11/site-packages/werkzeug/_internal.py L96  
[2023-10-08 11:28:32,624] DEBUG add_analista() L89   Adicionando o analista 'Pedro Costa na base de dados - call_trace=/home/phcosta/Documents/ticket/api/app.py L89  
[2023-10-08 11:28:32,646] DEBUG add_analista() L97   Pedro Costa adicionado com sucesso. - call_trace=/home/phcosta/Documents/ticket/api/app.py L97  
[2023-10-08 11:28:32,646] INFO _log() L96   192.168.0.15 - - [08/Oct/2023 11:28:32] "POST /analista HTTP/1.1" 200 - - call_trace=/home/phcosta/Documents/ticket/api/venv/lib/python3.11/site-packages/werkzeug/_internal.py L96  
[2023-10-08 11:28:45,400] DEBUG get_analistas() L37   Coletando Analistas - call_trace=/home/phcosta/Documents/ticket/api/app.py L37  
[2023-10-08 11:28:45,407] DEBUG get_analistas() L47   1 Analistas encontrados - call_trace=/home/phcosta/Documents/ticket/api/app.py L47  
[2023-10-08 11:28:45,407] INFO _log() L96   192.168.0.15 - - [08/Oct/2023 11:28:45] "GET /analistas HTTP/1.1" 200 - - call_trace=/home/phcosta/Documents/ticket/api/venv/lib/python3.11/site-packages/werkzeug/_internal.py L96  
[2023-10-08 11:32:15,978] INFO _log() L96    * Detected change in '/home/phcosta/Documents/ticket/api/model/analista/processo.py', reloading - call_trace=/home/phcosta/Documents/ticket/api/venv/lib/python3.11/site-packages/werkzeug/_internal.py L96  
[2023-10-08 11:32:21,676] DEBUG get_processos() L170  Coletando Processos - call_trace=/home/phcosta/Documents/ticket/api/app.py L170 
[2023-10-08 11:32:21,693] INFO _log() L96   192.168.0.15 - - [08/Oct/2023 11:32:21] "GET /processos HTTP/1.1" 200 - - call_trace=/home/phcosta/Documents/ticket/api/venv/lib/python3.11/site-packages/werkzeug/_internal.py L96  
[2023-10-08 11:32:24,832] DEBUG get_analistas() L37   Coletando Analistas - call_trace=/home/phcosta/Documents/ticket/api/app.py L37  
[2023-10-08 11:32:24,840] DEBUG get_analistas() L47   1 Analistas encontrados - call_trace=/home/phcosta/Documents/ticket/api/app.py L47  
[2023-10-08 11:32:24,840] INFO _log() L96   192.168.0.15 - - [08/Oct/2023 11:32:24] "GET /analistas HTTP/1.1" 200 - - call_trace=/home/phcosta/Documents/ticket/api/venv/lib/python3.11/site-packages/werkzeug/_internal.py L96  
[2023-10-08 11:33:02,578] INFO _log() L96    * Detected change in '/home/phcosta/Documents/ticket/api/model/analista/analista.py', reloading - call_trace=/home/phcosta/Documents/ticket/api/venv/lib/python3.11/site-packages/werkzeug/_internal.py L96  
[2023-10-08 11:33:04,158] DEBUG get_analistas() L37   Coletando Analistas - call_trace=/home/phcosta/Documents/ticket/api/app.py L37  
[2023-10-08 11:33:04,159] ERROR log_exception() L1414 Exception on /analistas [GET] - call_trace=/home/phcosta/Documents/ticket/api/venv/lib/python3.11/site-packages/flask/app.py L1414
Traceback (most recent call last):
  File "/home/phcosta/Documents/ticket/api/venv/lib/python3.11/site-packages/flask/app.py", line 2190, in wsgi_app
    response = self.full_dispatch_request()
               ^^^^^^^^^^^^^^^^^^^^^^^^^^^^
  File "/home/phcosta/Documents/ticket/api/venv/lib/python3.11/site-packages/flask/app.py", line 1486, in full_dispatch_request
    rv = self.handle_user_exception(e)
         ^^^^^^^^^^^^^^^^^^^^^^^^^^^^^
  File "/home/phcosta/Documents/ticket/api/venv/lib/python3.11/site-packages/flask_cors/extension.py", line 176, in wrapped_function
    return cors_after_request(app.make_response(f(*args, **kwargs)))
                                                ^^^^^^^^^^^^^^^^^^
  File "/home/phcosta/Documents/ticket/api/venv/lib/python3.11/site-packages/flask/app.py", line 1484, in full_dispatch_request
    rv = self.dispatch_request()
         ^^^^^^^^^^^^^^^^^^^^^^^
  File "/home/phcosta/Documents/ticket/api/venv/lib/python3.11/site-packages/flask/app.py", line 1469, in dispatch_request
    return self.ensure_sync(self.view_functions[rule.endpoint])(**view_args)
           ^^^^^^^^^^^^^^^^^^^^^^^^^^^^^^^^^^^^^^^^^^^^^^^^^^^^^^^^^^^^^^^^^
  File "/home/phcosta/Documents/ticket/api/venv/lib/python3.11/site-packages/flask_openapi3/scaffold.py", line 127, in view_func
    response = func(**func_kwargs)
               ^^^^^^^^^^^^^^^^^^^
  File "/home/phcosta/Documents/ticket/api/app.py", line 41, in get_analistas
    analistas = session.query(Analista).all()
                ^^^^^^^^^^^^^^^^^^^^^^^
  File "/home/phcosta/Documents/ticket/api/venv/lib/python3.11/site-packages/sqlalchemy/orm/session.py", line 2830, in query
    return self._query_cls(entities, self, **kwargs)
           ^^^^^^^^^^^^^^^^^^^^^^^^^^^^^^^^^^^^^^^^^
  File "/home/phcosta/Documents/ticket/api/venv/lib/python3.11/site-packages/sqlalchemy/orm/query.py", line 274, in __init__
    self._set_entities(entities)
  File "/home/phcosta/Documents/ticket/api/venv/lib/python3.11/site-packages/sqlalchemy/orm/query.py", line 283, in _set_entities
    self._raw_columns = [
                        ^
  File "/home/phcosta/Documents/ticket/api/venv/lib/python3.11/site-packages/sqlalchemy/orm/query.py", line 284, in <listcomp>
    coercions.expect(
  File "/home/phcosta/Documents/ticket/api/venv/lib/python3.11/site-packages/sqlalchemy/sql/coercions.py", line 406, in expect
    insp._post_inspect
  File "/home/phcosta/Documents/ticket/api/venv/lib/python3.11/site-packages/sqlalchemy/util/langhelpers.py", line 1252, in __get__
    obj.__dict__[self.__name__] = result = self.fget(obj)
                                           ^^^^^^^^^^^^^^
  File "/home/phcosta/Documents/ticket/api/venv/lib/python3.11/site-packages/sqlalchemy/orm/mapper.py", line 2707, in _post_inspect
    self._check_configure()
  File "/home/phcosta/Documents/ticket/api/venv/lib/python3.11/site-packages/sqlalchemy/orm/mapper.py", line 2386, in _check_configure
    _configure_registries({self.registry}, cascade=True)
  File "/home/phcosta/Documents/ticket/api/venv/lib/python3.11/site-packages/sqlalchemy/orm/mapper.py", line 4199, in _configure_registries
    _do_configure_registries(registries, cascade)
  File "/home/phcosta/Documents/ticket/api/venv/lib/python3.11/site-packages/sqlalchemy/orm/mapper.py", line 4240, in _do_configure_registries
    mapper._post_configure_properties()
  File "/home/phcosta/Documents/ticket/api/venv/lib/python3.11/site-packages/sqlalchemy/orm/mapper.py", line 2403, in _post_configure_properties
    prop.init()
  File "/home/phcosta/Documents/ticket/api/venv/lib/python3.11/site-packages/sqlalchemy/orm/interfaces.py", line 579, in init
    self.do_init()
  File "/home/phcosta/Documents/ticket/api/venv/lib/python3.11/site-packages/sqlalchemy/orm/relationships.py", line 1639, in do_init
    self._generate_backref()
  File "/home/phcosta/Documents/ticket/api/venv/lib/python3.11/site-packages/sqlalchemy/orm/relationships.py", line 2070, in _generate_backref
    raise sa_exc.ArgumentError(
sqlalchemy.exc.ArgumentError: Error creating backref 'analistas' on relationship 'Analista.processos': property of that name exists on mapper 'Mapper[Processo(processo)]'
[2023-10-08 11:33:04,163] INFO _log() L96   192.168.0.15 - - [08/Oct/2023 11:33:04] "[35m[1mGET /analistas HTTP/1.1[0m" 500 - - call_trace=/home/phcosta/Documents/ticket/api/venv/lib/python3.11/site-packages/werkzeug/_internal.py L96  
[2023-10-08 11:33:08,086] INFO _log() L96    * Detected change in '/home/phcosta/Documents/ticket/api/model/analista/analista.py', reloading - call_trace=/home/phcosta/Documents/ticket/api/venv/lib/python3.11/site-packages/werkzeug/_internal.py L96  
[2023-10-08 11:33:08,827] DEBUG get_analistas() L37   Coletando Analistas - call_trace=/home/phcosta/Documents/ticket/api/app.py L37  
[2023-10-08 11:33:08,832] DEBUG get_analistas() L47   1 Analistas encontrados - call_trace=/home/phcosta/Documents/ticket/api/app.py L47  
[2023-10-08 11:33:08,833] INFO _log() L96   192.168.0.15 - - [08/Oct/2023 11:33:08] "GET /analistas HTTP/1.1" 200 - - call_trace=/home/phcosta/Documents/ticket/api/venv/lib/python3.11/site-packages/werkzeug/_internal.py L96  
[2023-10-08 11:34:29,454] DEBUG get_analistas() L37   Coletando Analistas - call_trace=/home/phcosta/Documents/ticket/api/app.py L37  
[2023-10-08 11:34:29,461] DEBUG get_analistas() L47   1 Analistas encontrados - call_trace=/home/phcosta/Documents/ticket/api/app.py L47  
