[2023-10-08 11:09:09,284] INFO _log() L96   192.168.0.15 - - [08/Oct/2023 11:09:09] "[33mGET /analistas HTTP/1.1[0m" 404 - - call_trace=/home/phcosta/Documents/ticket/api/venv/lib/python3.11/site-packages/werkzeug/_internal.py L96  
[2023-10-08 11:09:10,068] INFO _log() L96   192.168.0.15 - - [08/Oct/2023 11:09:10] "[33mGET /analistas HTTP/1.1[0m" 404 - - call_trace=/home/phcosta/Documents/ticket/api/venv/lib/python3.11/site-packages/werkzeug/_internal.py L96  
[2023-10-08 11:09:10,220] INFO _log() L96   192.168.0.15 - - [08/Oct/2023 11:09:10] "[33mGET /analistas HTTP/1.1[0m" 404 - - call_trace=/home/phcosta/Documents/ticket/api/venv/lib/python3.11/site-packages/werkzeug/_internal.py L96  
[2023-10-08 11:09:10,386] INFO _log() L96   192.168.0.15 - - [08/Oct/2023 11:09:10] "[33mGET /analistas HTTP/1.1[0m" 404 - - call_trace=/home/phcosta/Documents/ticket/api/venv/lib/python3.11/site-packages/werkzeug/_internal.py L96  
[2023-10-08 11:09:10,544] INFO _log() L96   192.168.0.15 - - [08/Oct/2023 11:09:10] "[33mGET /analistas HTTP/1.1[0m" 404 - - call_trace=/home/phcosta/Documents/ticket/api/venv/lib/python3.11/site-packages/werkzeug/_internal.py L96  
[2023-10-08 11:09:10,707] INFO _log() L96   192.168.0.15 - - [08/Oct/2023 11:09:10] "[33mGET /analistas HTTP/1.1[0m" 404 - - call_trace=/home/phcosta/Documents/ticket/api/venv/lib/python3.11/site-packages/werkzeug/_internal.py L96  
[2023-10-08 11:09:33,194] INFO _log() L96    * Detected change in '/home/phcosta/Documents/ticket/api/app.py', reloading - call_trace=/home/phcosta/Documents/ticket/api/venv/lib/python3.11/site-packages/werkzeug/_internal.py L96  
[2023-10-08 11:09:35,200] ERROR log_exception() L1414 Exception on /analistas [GET] - call_trace=/home/phcosta/Documents/ticket/api/venv/lib/python3.11/site-packages/flask/app.py L1414
Traceback (most recent call last):
  File "/home/phcosta/Documents/ticket/api/venv/lib/python3.11/site-packages/flask/app.py", line 2190, in wsgi_app
    response = self.full_dispatch_request()
               ^^^^^^^^^^^^^^^^^^^^^^^^^^^^
  File "/home/phcosta/Documents/ticket/api/venv/lib/python3.11/site-packages/flask/app.py", line 1486, in full_dispatch_request
    rv = self.handle_user_exception(e)
         ^^^^^^^^^^^^^^^^^^^^^^^^^^^^^
  File "/home/phcosta/Documents/ticket/api/venv/lib/python3.11/site-packages/flask_cors/extension.py", line 176, in wrapped_function
    return cors_after_request(app.make_response(f(*args, **kwargs)))
                                                ^^^^^^^^^^^^^^^^^^
  File "/home/phcosta/Documents/ticket/api/venv/lib/python3.11/site-packages/flask/app.py", line 1484, in full_dispatch_request
    rv = self.dispatch_request()
         ^^^^^^^^^^^^^^^^^^^^^^^
  File "/home/phcosta/Documents/ticket/api/venv/lib/python3.11/site-packages/flask/app.py", line 1469, in dispatch_request
    return self.ensure_sync(self.view_functions[rule.endpoint])(**view_args)
           ^^^^^^^^^^^^^^^^^^^^^^^^^^^^^^^^^^^^^^^^^^^^^^^^^^^^^^^^^^^^^^^^^
  File "/home/phcosta/Documents/ticket/api/route/analista/analista.py", line 23, in get_analistas
    analistas = session.query(Analista).all()
                ^^^^^^^^^^^^^^^^^^^^^^^
  File "/home/phcosta/Documents/ticket/api/venv/lib/python3.11/site-packages/sqlalchemy/orm/session.py", line 2830, in query
    return self._query_cls(entities, self, **kwargs)
           ^^^^^^^^^^^^^^^^^^^^^^^^^^^^^^^^^^^^^^^^^
  File "/home/phcosta/Documents/ticket/api/venv/lib/python3.11/site-packages/sqlalchemy/orm/query.py", line 274, in __init__
    self._set_entities(entities)
  File "/home/phcosta/Documents/ticket/api/venv/lib/python3.11/site-packages/sqlalchemy/orm/query.py", line 283, in _set_entities
    self._raw_columns = [
                        ^
  File "/home/phcosta/Documents/ticket/api/venv/lib/python3.11/site-packages/sqlalchemy/orm/query.py", line 284, in <listcomp>
    coercions.expect(
  File "/home/phcosta/Documents/ticket/api/venv/lib/python3.11/site-packages/sqlalchemy/sql/coercions.py", line 406, in expect
    insp._post_inspect
  File "/home/phcosta/Documents/ticket/api/venv/lib/python3.11/site-packages/sqlalchemy/util/langhelpers.py", line 1252, in __get__
    obj.__dict__[self.__name__] = result = self.fget(obj)
                                           ^^^^^^^^^^^^^^
  File "/home/phcosta/Documents/ticket/api/venv/lib/python3.11/site-packages/sqlalchemy/orm/mapper.py", line 2707, in _post_inspect
    self._check_configure()
  File "/home/phcosta/Documents/ticket/api/venv/lib/python3.11/site-packages/sqlalchemy/orm/mapper.py", line 2386, in _check_configure
    _configure_registries({self.registry}, cascade=True)
  File "/home/phcosta/Documents/ticket/api/venv/lib/python3.11/site-packages/sqlalchemy/orm/mapper.py", line 4199, in _configure_registries
    _do_configure_registries(registries, cascade)
  File "/home/phcosta/Documents/ticket/api/venv/lib/python3.11/site-packages/sqlalchemy/orm/mapper.py", line 4240, in _do_configure_registries
    mapper._post_configure_properties()
  File "/home/phcosta/Documents/ticket/api/venv/lib/python3.11/site-packages/sqlalchemy/orm/mapper.py", line 2403, in _post_configure_properties
    prop.init()
  File "/home/phcosta/Documents/ticket/api/venv/lib/python3.11/site-packages/sqlalchemy/orm/interfaces.py", line 579, in init
    self.do_init()
  File "/home/phcosta/Documents/ticket/api/venv/lib/python3.11/site-packages/sqlalchemy/orm/relationships.py", line 1639, in do_init
    self._generate_backref()
  File "/home/phcosta/Documents/ticket/api/venv/lib/python3.11/site-packages/sqlalchemy/orm/relationships.py", line 2070, in _generate_backref
    raise sa_exc.ArgumentError(
sqlalchemy.exc.ArgumentError: Error creating backref 'analistas' on relationship 'Analista.processos': property of that name exists on mapper 'Mapper[Processo(processo)]'
[2023-10-08 11:09:35,203] INFO _log() L96   192.168.0.15 - - [08/Oct/2023 11:09:35] "[35m[1mGET /analistas HTTP/1.1[0m" 500 - - call_trace=/home/phcosta/Documents/ticket/api/venv/lib/python3.11/site-packages/werkzeug/_internal.py L96  
[2023-10-08 11:10:07,781] INFO _log() L96    * Detected change in '/home/phcosta/Documents/ticket/api/app.py', reloading - call_trace=/home/phcosta/Documents/ticket/api/venv/lib/python3.11/site-packages/werkzeug/_internal.py L96  
