[2023-10-08 12:10:48,481] INFO _log() L96    * Restarting with stat - call_trace=/home/phcosta/Documents/ticket/api/venv/lib/python3.11/site-packages/werkzeug/_internal.py L96  
[2023-10-08 12:10:49,063] INFO _log() L96   192.168.0.15 - - [08/Oct/2023 12:10:49] "[35m[1mGET /processos HTTP/1.1[0m" 500 - - call_trace=/home/phcosta/Documents/ticket/api/venv/lib/python3.11/site-packages/werkzeug/_internal.py L96  
[2023-10-08 12:10:49,066] ERROR _log() L96   Error on request:
Traceback (most recent call last):
  File "/home/phcosta/Documents/ticket/api/venv/lib/python3.11/site-packages/werkzeug/serving.py", line 362, in run_wsgi
    execute(self.server.app)
  File "/home/phcosta/Documents/ticket/api/venv/lib/python3.11/site-packages/werkzeug/serving.py", line 323, in execute
    application_iter = app(environ, start_response)
                       ^^^^^^^^^^^^^^^^^^^^^^^^^^^^
  File "/home/phcosta/Documents/ticket/api/venv/lib/python3.11/site-packages/flask/cli.py", line 907, in app
    raise err from None
  File "/home/phcosta/Documents/ticket/api/venv/lib/python3.11/site-packages/flask/cli.py", line 898, in run_command
    app = info.load_app()
          ^^^^^^^^^^^^^^^
  File "/home/phcosta/Documents/ticket/api/venv/lib/python3.11/site-packages/flask/cli.py", line 313, in load_app
    app = locate_app(import_name, None, raise_if_not_found=False)
          ^^^^^^^^^^^^^^^^^^^^^^^^^^^^^^^^^^^^^^^^^^^^^^^^^^^^^^^
  File "/home/phcosta/Documents/ticket/api/venv/lib/python3.11/site-packages/flask/cli.py", line 224, in locate_app
    raise NoAppException(
flask.cli.NoAppException: While importing 'app', an ImportError was raised:

Traceback (most recent call last):
  File "/home/phcosta/Documents/ticket/api/venv/lib/python3.11/site-packages/flask/cli.py", line 219, in locate_app
    __import__(module_name)
  File "/home/phcosta/Documents/ticket/api/app.py", line 9, in <module>
    from route import configure_analista_routes
  File "/home/phcosta/Documents/ticket/api/route/__init__.py", line 2, in <module>
    from route.analista.processo import configure_analista_routes
ImportError: cannot import name 'configure_analista_routes' from 'route.analista.processo' (/home/phcosta/Documents/ticket/api/route/analista/processo.py) - call_trace=/home/phcosta/Documents/ticket/api/venv/lib/python3.11/site-packages/werkzeug/_internal.py L96  
[2023-10-08 12:11:11,972] INFO _log() L96    * Detected change in '/home/phcosta/Documents/ticket/api/route/__init__.py', reloading - call_trace=/home/phcosta/Documents/ticket/api/venv/lib/python3.11/site-packages/werkzeug/_internal.py L96  
[2023-10-08 12:11:12,070] INFO _log() L96    * Restarting with stat - call_trace=/home/phcosta/Documents/ticket/api/venv/lib/python3.11/site-packages/werkzeug/_internal.py L96  
[2023-10-08 12:11:14,788] INFO _log() L96   192.168.0.15 - - [08/Oct/2023 12:11:14] "[35m[1mGET /processos HTTP/1.1[0m" 500 - - call_trace=/home/phcosta/Documents/ticket/api/venv/lib/python3.11/site-packages/werkzeug/_internal.py L96  
[2023-10-08 12:11:14,791] ERROR _log() L96   Error on request:
Traceback (most recent call last):
  File "/home/phcosta/Documents/ticket/api/venv/lib/python3.11/site-packages/werkzeug/serving.py", line 362, in run_wsgi
    execute(self.server.app)
  File "/home/phcosta/Documents/ticket/api/venv/lib/python3.11/site-packages/werkzeug/serving.py", line 323, in execute
    application_iter = app(environ, start_response)
                       ^^^^^^^^^^^^^^^^^^^^^^^^^^^^
  File "/home/phcosta/Documents/ticket/api/venv/lib/python3.11/site-packages/flask/cli.py", line 907, in app
    raise err from None
  File "/home/phcosta/Documents/ticket/api/venv/lib/python3.11/site-packages/flask/cli.py", line 898, in run_command
    app = info.load_app()
          ^^^^^^^^^^^^^^^
  File "/home/phcosta/Documents/ticket/api/venv/lib/python3.11/site-packages/flask/cli.py", line 313, in load_app
    app = locate_app(import_name, None, raise_if_not_found=False)
          ^^^^^^^^^^^^^^^^^^^^^^^^^^^^^^^^^^^^^^^^^^^^^^^^^^^^^^^
  File "/home/phcosta/Documents/ticket/api/venv/lib/python3.11/site-packages/flask/cli.py", line 219, in locate_app
    __import__(module_name)
  File "/home/phcosta/Documents/ticket/api/app.py", line 34, in <module>
    configure_processo_routes(app)
NameError: name 'configure_processo_routes' is not defined - call_trace=/home/phcosta/Documents/ticket/api/venv/lib/python3.11/site-packages/werkzeug/_internal.py L96  
[2023-10-08 12:11:36,557] INFO _log() L96    * Detected change in '/home/phcosta/Documents/ticket/api/app.py', reloading - call_trace=/home/phcosta/Documents/ticket/api/venv/lib/python3.11/site-packages/werkzeug/_internal.py L96  
[2023-10-08 12:11:36,660] INFO _log() L96    * Restarting with stat - call_trace=/home/phcosta/Documents/ticket/api/venv/lib/python3.11/site-packages/werkzeug/_internal.py L96  
[2023-10-08 12:11:39,900] DEBUG get_processos() L22   Coletando Processos - call_trace=/home/phcosta/Documents/ticket/api/route/analista/processo.py L22  
[2023-10-08 12:11:39,908] DEBUG get_processos() L32   1 Processos encontrados - call_trace=/home/phcosta/Documents/ticket/api/route/analista/processo.py L32  
[2023-10-08 12:11:39,909] INFO _log() L96   192.168.0.15 - - [08/Oct/2023 12:11:39] "GET /processos HTTP/1.1" 200 - - call_trace=/home/phcosta/Documents/ticket/api/venv/lib/python3.11/site-packages/werkzeug/_internal.py L96  
[2023-10-08 12:11:44,286] INFO _log() L96   192.168.0.15 - - [08/Oct/2023 12:11:44] "GET /openapi/swagger HTTP/1.1" 200 - - call_trace=/home/phcosta/Documents/ticket/api/venv/lib/python3.11/site-packages/werkzeug/_internal.py L96  
[2023-10-08 12:11:44,307] INFO _log() L96   192.168.0.15 - - [08/Oct/2023 12:11:44] "[36mGET /openapi/static/js/swagger-ui-bundle.js HTTP/1.1[0m" 304 - - call_trace=/home/phcosta/Documents/ticket/api/venv/lib/python3.11/site-packages/werkzeug/_internal.py L96  
[2023-10-08 12:11:44,308] INFO _log() L96   192.168.0.15 - - [08/Oct/2023 12:11:44] "[36mGET /openapi/static/css/swagger-ui.css HTTP/1.1[0m" 304 - - call_trace=/home/phcosta/Documents/ticket/api/venv/lib/python3.11/site-packages/werkzeug/_internal.py L96  
[2023-10-08 12:11:44,308] INFO _log() L96   192.168.0.15 - - [08/Oct/2023 12:11:44] "[36mGET /openapi/static/js/swagger-ui-standalone-preset.js HTTP/1.1[0m" 304 - - call_trace=/home/phcosta/Documents/ticket/api/venv/lib/python3.11/site-packages/werkzeug/_internal.py L96  
[2023-10-08 12:11:44,410] INFO _log() L96   192.168.0.15 - - [08/Oct/2023 12:11:44] "GET /openapi/openapi.json HTTP/1.1" 200 - - call_trace=/home/phcosta/Documents/ticket/api/venv/lib/python3.11/site-packages/werkzeug/_internal.py L96  
[2023-10-08 12:11:52,251] DEBUG get_processos() L22   Coletando Processos - call_trace=/home/phcosta/Documents/ticket/api/route/analista/processo.py L22  
[2023-10-08 12:11:52,252] DEBUG get_processos() L32   1 Processos encontrados - call_trace=/home/phcosta/Documents/ticket/api/route/analista/processo.py L32  
[2023-10-08 12:11:52,253] INFO _log() L96   192.168.0.15 - - [08/Oct/2023 12:11:52] "GET /processos HTTP/1.1" 200 - - call_trace=/home/phcosta/Documents/ticket/api/venv/lib/python3.11/site-packages/werkzeug/_internal.py L96  
[2023-10-08 12:11:59,244] DEBUG del_processo() L128  Deletando dados sobre processo #1 - call_trace=/home/phcosta/Documents/ticket/api/route/analista/processo.py L128 
[2023-10-08 12:11:59,268] DEBUG del_processo() L137  Deletado o Processo #1 - call_trace=/home/phcosta/Documents/ticket/api/route/analista/processo.py L137 
[2023-10-08 12:11:59,268] INFO _log() L96   192.168.0.15 - - [08/Oct/2023 12:11:59] "DELETE /processo?id=1 HTTP/1.1" 200 - - call_trace=/home/phcosta/Documents/ticket/api/venv/lib/python3.11/site-packages/werkzeug/_internal.py L96  
[2023-10-08 12:12:04,539] DEBUG del_processo() L128  Deletando dados sobre processo #1 - call_trace=/home/phcosta/Documents/ticket/api/route/analista/processo.py L128 
[2023-10-08 12:12:04,540] WARNING del_processo() L142  Erro ao deletar o Processo #'1', Processo n√£o encontrado na base - call_trace=/home/phcosta/Documents/ticket/api/route/analista/processo.py L142 
[2023-10-08 12:12:04,540] INFO _log() L96   192.168.0.15 - - [08/Oct/2023 12:12:04] "[33mDELETE /processo?id=1 HTTP/1.1[0m" 404 - - call_trace=/home/phcosta/Documents/ticket/api/venv/lib/python3.11/site-packages/werkzeug/_internal.py L96  
[2023-10-08 12:31:20,333] INFO _log() L96    * Detected change in '/home/phcosta/Documents/ticket/api/app.py', reloading - call_trace=/home/phcosta/Documents/ticket/api/venv/lib/python3.11/site-packages/werkzeug/_internal.py L96  
[2023-10-08 12:31:20,452] INFO _log() L96    * Restarting with stat - call_trace=/home/phcosta/Documents/ticket/api/venv/lib/python3.11/site-packages/werkzeug/_internal.py L96  
[2023-10-08 12:31:23,784] INFO _log() L96   192.168.0.15 - - [08/Oct/2023 12:31:23] "GET /openapi/swagger HTTP/1.1" 200 - - call_trace=/home/phcosta/Documents/ticket/api/venv/lib/python3.11/site-packages/werkzeug/_internal.py L96  
[2023-10-08 12:31:23,809] INFO _log() L96   192.168.0.15 - - [08/Oct/2023 12:31:23] "[36mGET /openapi/static/css/swagger-ui.css HTTP/1.1[0m" 304 - - call_trace=/home/phcosta/Documents/ticket/api/venv/lib/python3.11/site-packages/werkzeug/_internal.py L96  
[2023-10-08 12:31:23,810] INFO _log() L96   192.168.0.15 - - [08/Oct/2023 12:31:23] "[36mGET /openapi/static/js/swagger-ui-bundle.js HTTP/1.1[0m" 304 - - call_trace=/home/phcosta/Documents/ticket/api/venv/lib/python3.11/site-packages/werkzeug/_internal.py L96  
[2023-10-08 12:31:23,810] INFO _log() L96   192.168.0.15 - - [08/Oct/2023 12:31:23] "[36mGET /openapi/static/js/swagger-ui-standalone-preset.js HTTP/1.1[0m" 304 - - call_trace=/home/phcosta/Documents/ticket/api/venv/lib/python3.11/site-packages/werkzeug/_internal.py L96  
