[2023-10-08 12:08:44,575] INFO _log() L96   192.168.0.15 - - [08/Oct/2023 12:08:44] "[36mGET /openapi/static/js/swagger-ui-bundle.js HTTP/1.1[0m" 304 - - call_trace=/home/phcosta/Documents/ticket/api/venv/lib/python3.11/site-packages/werkzeug/_internal.py L96  
[2023-10-08 12:08:44,576] INFO _log() L96   192.168.0.15 - - [08/Oct/2023 12:08:44] "[36mGET /openapi/static/js/swagger-ui-standalone-preset.js HTTP/1.1[0m" 304 - - call_trace=/home/phcosta/Documents/ticket/api/venv/lib/python3.11/site-packages/werkzeug/_internal.py L96  
[2023-10-08 12:08:44,675] INFO _log() L96   192.168.0.15 - - [08/Oct/2023 12:08:44] "GET /openapi/openapi.json HTTP/1.1" 200 - - call_trace=/home/phcosta/Documents/ticket/api/venv/lib/python3.11/site-packages/werkzeug/_internal.py L96  
[2023-10-08 12:08:50,718] INFO _log() L96   192.168.0.15 - - [08/Oct/2023 12:08:50] "[33mGET /processos HTTP/1.1[0m" 404 - - call_trace=/home/phcosta/Documents/ticket/api/venv/lib/python3.11/site-packages/werkzeug/_internal.py L96  
[2023-10-08 12:09:22,064] INFO _log() L96    * Detected change in '/home/phcosta/Documents/ticket/api/route/__init__.py', reloading - call_trace=/home/phcosta/Documents/ticket/api/venv/lib/python3.11/site-packages/werkzeug/_internal.py L96  
[2023-10-08 12:10:16,768] INFO _log() L96    * Detected change in '/home/phcosta/Documents/ticket/api/route/analista/processo.py', reloading - call_trace=/home/phcosta/Documents/ticket/api/venv/lib/python3.11/site-packages/werkzeug/_internal.py L96  
[2023-10-08 12:10:20,035] INFO _log() L96   192.168.0.15 - - [08/Oct/2023 12:10:20] "[35m[1mGET /processos HTTP/1.1[0m" 500 - - call_trace=/home/phcosta/Documents/ticket/api/venv/lib/python3.11/site-packages/werkzeug/_internal.py L96  
[2023-10-08 12:10:20,038] ERROR _log() L96   Error on request:
Traceback (most recent call last):
  File "/home/phcosta/Documents/ticket/api/venv/lib/python3.11/site-packages/werkzeug/serving.py", line 362, in run_wsgi
    execute(self.server.app)
  File "/home/phcosta/Documents/ticket/api/venv/lib/python3.11/site-packages/werkzeug/serving.py", line 323, in execute
    application_iter = app(environ, start_response)
                       ^^^^^^^^^^^^^^^^^^^^^^^^^^^^
  File "/home/phcosta/Documents/ticket/api/venv/lib/python3.11/site-packages/flask/cli.py", line 907, in app
    raise err from None
  File "/home/phcosta/Documents/ticket/api/venv/lib/python3.11/site-packages/flask/cli.py", line 898, in run_command
    app = info.load_app()
          ^^^^^^^^^^^^^^^
  File "/home/phcosta/Documents/ticket/api/venv/lib/python3.11/site-packages/flask/cli.py", line 313, in load_app
    app = locate_app(import_name, None, raise_if_not_found=False)
          ^^^^^^^^^^^^^^^^^^^^^^^^^^^^^^^^^^^^^^^^^^^^^^^^^^^^^^^
  File "/home/phcosta/Documents/ticket/api/venv/lib/python3.11/site-packages/flask/cli.py", line 224, in locate_app
    raise NoAppException(
flask.cli.NoAppException: While importing 'app', an ImportError was raised:

Traceback (most recent call last):
  File "/home/phcosta/Documents/ticket/api/venv/lib/python3.11/site-packages/flask/cli.py", line 219, in locate_app
    __import__(module_name)
  File "/home/phcosta/Documents/ticket/api/app.py", line 9, in <module>
    from route import configure_analista_routes
  File "/home/phcosta/Documents/ticket/api/route/__init__.py", line 2, in <module>
    from route.analista.processo import configure_analista_routes
ImportError: cannot import name 'configure_analista_routes' from 'route.analista.processo' (/home/phcosta/Documents/ticket/api/route/analista/processo.py) - call_trace=/home/phcosta/Documents/ticket/api/venv/lib/python3.11/site-packages/werkzeug/_internal.py L96  
[2023-10-08 12:10:20,804] INFO _log() L96   192.168.0.15 - - [08/Oct/2023 12:10:20] "[35m[1mGET /processos HTTP/1.1[0m" 500 - - call_trace=/home/phcosta/Documents/ticket/api/venv/lib/python3.11/site-packages/werkzeug/_internal.py L96  
[2023-10-08 12:10:20,805] ERROR _log() L96   Error on request:
Traceback (most recent call last):
  File "/home/phcosta/Documents/ticket/api/venv/lib/python3.11/site-packages/werkzeug/serving.py", line 362, in run_wsgi
    execute(self.server.app)
  File "/home/phcosta/Documents/ticket/api/venv/lib/python3.11/site-packages/werkzeug/serving.py", line 323, in execute
    application_iter = app(environ, start_response)
                       ^^^^^^^^^^^^^^^^^^^^^^^^^^^^
  File "/home/phcosta/Documents/ticket/api/venv/lib/python3.11/site-packages/flask/cli.py", line 907, in app
    raise err from None
  File "/home/phcosta/Documents/ticket/api/venv/lib/python3.11/site-packages/werkzeug/serving.py", line 362, in run_wsgi
    execute(self.server.app)
  File "/home/phcosta/Documents/ticket/api/venv/lib/python3.11/site-packages/werkzeug/serving.py", line 323, in execute
    application_iter = app(environ, start_response)
                       ^^^^^^^^^^^^^^^^^^^^^^^^^^^^
  File "/home/phcosta/Documents/ticket/api/venv/lib/python3.11/site-packages/flask/cli.py", line 907, in app
    raise err from None
  File "/home/phcosta/Documents/ticket/api/venv/lib/python3.11/site-packages/flask/cli.py", line 898, in run_command
    app = info.load_app()
          ^^^^^^^^^^^^^^^
  File "/home/phcosta/Documents/ticket/api/venv/lib/python3.11/site-packages/flask/cli.py", line 313, in load_app
    app = locate_app(import_name, None, raise_if_not_found=False)
          ^^^^^^^^^^^^^^^^^^^^^^^^^^^^^^^^^^^^^^^^^^^^^^^^^^^^^^^
  File "/home/phcosta/Documents/ticket/api/venv/lib/python3.11/site-packages/flask/cli.py", line 224, in locate_app
    raise NoAppException(
flask.cli.NoAppException: While importing 'app', an ImportError was raised:

Traceback (most recent call last):
  File "/home/phcosta/Documents/ticket/api/venv/lib/python3.11/site-packages/flask/cli.py", line 219, in locate_app
    __import__(module_name)
  File "/home/phcosta/Documents/ticket/api/app.py", line 9, in <module>
    from route import configure_analista_routes
  File "/home/phcosta/Documents/ticket/api/route/__init__.py", line 2, in <module>
    from route.analista.processo import configure_analista_routes
ImportError: cannot import name 'configure_analista_routes' from 'route.analista.processo' (/home/phcosta/Documents/ticket/api/route/analista/processo.py) - call_trace=/home/phcosta/Documents/ticket/api/venv/lib/python3.11/site-packages/werkzeug/_internal.py L96  
[2023-10-08 12:10:48,386] INFO _log() L96    * Detected change in '/home/phcosta/Documents/ticket/api/app.py', reloading - call_trace=/home/phcosta/Documents/ticket/api/venv/lib/python3.11/site-packages/werkzeug/_internal.py L96  
